Workbook

Sheet Cover
B2: INVIRTUS
B3: Bottoms-Up Revenue Potential (two streams; TAM / SAM / SOM equivalents)
B4: Candidate assessment platform - decision intelligence layer above the ATS | USD | Built 2026-06-16
B6: THE ANSWER
B7: Lead with the 3-year reachable number. It runs on two streams - assessment packs plus talent-DB monetization - and is driven first by the Manatal channel (embedded attach ~59% of the assessment line), then self-serve. The single biggest assumption is the Year-3 channel attach rate on the ICP-relevant Manatal base (Assumptions sec. 7); tests/account and the $14 PAYG price are the next two swing factors (see Sensitivity).
B11: FULL OPPORTUNITY | C11: SERVICEABLE TODAY | D11: 3-YEAR REACHABLE
B12: =Build!$F$37 | C12: =Build!$F$38 | D12: =Build!$F$39
B13: (TAM) all geos | 2 streams | C13: (SAM) focus-6 | serviceable | D13: (SOM) channel+direct | 3-yr
B15: 3-yr reachable - by revenue stream
B16: Assessment packs | C16: =Build!$C$39
B17: Talent-DB monetization | C17: =Build!$E$39
B18: Total revenue potential | C18: =Build!$F$39
B20: 3-yr reachable - assessments by route
B21: Channel (partner portfolio) | C21: =Build!$E$24
B22: Direct (self-serve + sales) | C22: =Build!$E$30
B24: Scenario levers (edit on Assumptions)
B25: Market breadth mode | C25: =Assumptions!$C$33
B26: Channel attach scalar | C26: =Assumptions!$C$90
B28: How to read this model
B29: 1. Every blue cell on Assumptions is an editable input; black cells are formulas with no hardcodes.
B30: 2. Market BREADTH toggle (1 Engineers / 2 White-collar / 3 Narrower) scales the universe; the
B31: headline above reflects the active mode. Channel is a partner PORTFOLIO (Manatal + others), each toggleable.
B32: 3. Build derives Serviceable bottoms-up (entities x %fit x tests/yr x net $/test), grosses up to Full
B33: opportunity, and captures the 3-yr figure via the partner channel + direct self-serve/sales, two streams.
B34: 4. Sensitivity flexes the inputs that move it most; Sources lists every researched figure.
B36: Input (editable) | C36: Formula (calc)

Sheet Assumptions
B1: INVIRTUS - Assumptions
B2: All blue cells are editable inputs. Black cells are formulas. Col E = source key (see Sources tab). Currency = USD.
B4: Driver | C4: Value | D4: Unit | E4: Src | F4: Logic / flag
B5: 1. Addressable entities (bottoms-up universe) [RESEARCH]
B6: Tech-focused recruiting agencies
B7: France | C7: 500 | D7: entities | E7: S1 | F7: Recruitment/staffing firms with a tech/IT desk. Tech subset of national agency base.
B8: UK | C8: 3500 | D8: entities | E8: S2 | F8: Recruitment/staffing firms with a tech/IT desk. Tech subset of national agency base.
B9: UAE | C9: 100 | D9: entities | E9: S3 | F9: Recruitment/staffing firms with a tech/IT desk. Tech subset of national agency base.
B10: Morocco | C10: 45 | D10: entities | E10: S4 | F10: Recruitment/staffing firms with a tech/IT desk. Tech subset of national agency base.
B11: KSA | C11: 50 | D11: entities | E11: S5 | F11: Recruitment/staffing firms with a tech/IT desk. Tech subset of national agency base.
B12: Egypt | C12: 60 | D12: entities | E12: S6 | F12: Recruitment/staffing firms with a tech/IT desk. Tech subset of national agency base.
B13: Engineering-heavy firms (tech/software/ICT cos.)
B14: France | C14: 95000 | D14: entities | E14: S1 | F14: Tech/software/ICT companies that hire engineers in-house.
B15: UK | C15: 107000 | D15: entities | E15: S2 | F15: Tech/software/ICT companies that hire engineers in-house.
B16: UAE | C16: 5000 | D16: entities | E16: S3 | F16: Tech/software/ICT companies that hire engineers in-house.
B17: Morocco | C17: 2000 | D17: entities | E17: S4 | F17: Tech/software/ICT companies that hire engineers in-house.
B18: KSA | C18: 1800 | D18: entities | E18: S5 | F18: Tech/software/ICT companies that hire engineers in-house.
B19: Egypt | C19: 2500 | D19: entities | E19: S6 | F19: Tech/software/ICT companies that hire engineers in-house.
B20: Mid-size firms w/ structured tech hiring (50-250)
B21: France | C21: 7300 | D21: entities | E21: S1 | F21: Medium enterprises x share that run structured engineering hiring.
B22: UK | C22: 13200 | D22: entities | E22: S2 | F22: Medium enterprises x share that run structured engineering hiring.
B23: UAE | C23: 2800 | D23: entities | E23: S3 | F23: Medium enterprises x share that run structured engineering hiring.
B24: Morocco | C24: 1250 | D24: entities | E24: S4 | F24: Medium enterprises x share that run structured engineering hiring.
B25: KSA | C25: 2600 | D25: entities | E25: S5 | F25: Medium enterprises x share that run structured engineering hiring.
B26: Egypt | C26: 2000 | D26: entities | E26: S6 | F26: Medium enterprises x share that run structured engineering hiring.
B27: Focus-6 subtotals (calc)
B28: Agencies - focus-6 total | C28: =(Assumptions!$C$7+Assumptions!$C$8+Assumptions!$C$9+Assumptions!$C$10+Assumptions!$C$11+Assumptions!$C$12) | D28: entities | F28: Sum across France, UK, UAE, Morocco, KSA, Egypt.
B29: Eng-heavy firms - focus-6 total | C29: =(Assumptions!$C$14+Assumptions!$C$15+Assumptions!$C$16+Assumptions!$C$17+Assumptions!$C$18+Assumptions!$C$19) | D29: entities | F29: Sum across France, UK, UAE, Morocco, KSA, Egypt.
B30: Mid-size firms - focus-6 total | C30: =(Assumptions!$C$21+Assumptions!$C$22+Assumptions!$C$23+Assumptions!$C$24+Assumptions!$C$25+Assumptions!$C$26) | D30: entities | F30: Sum across France, UK, UAE, Morocco, KSA, Egypt.
B31: 1b. Market breadth toggle (1=Engineers, 2=White-collar, 3=Narrower)
B32: Active breadth mode (1 / 2 / 3) | C32: 1 | D32: mode | F32: 1: tech/eng focus (current). 2: all structured white-collar hiring (Aida's broader view). 3: narrower high-conviction core.
B33: Active breadth (label) | C33: =CHOOSE(Assumptions!$C$32,"1 Engineers only","2 White-collar hiring","3 Narrower use case") | F33: Driven by the toggle above.
B34: Breadth multiplier by segment | C34: 1 Eng | D34: 2 White-collar | E34: 3 Narrower | F34: Logic
B35: Agencies | C35: 1 | D35: 7 | E35: 1 | F35: Tech agencies -> all recruitment agencies (tech ~10-15% of total).
B36: Eng-heavy firms | C36: 1 | D36: 4 | E36: 0.5 | F36: Tech firms -> all firms with structured white-collar hiring.
B37: Mid-size firms | C37: 1 | D37: 3 | E37: 0.2 | F37: Eng-hiring mid-size -> all mid-size structured hirers (2) / core only (3).
B38: Effective addressable entities (calc = subtotal x active breadth mult)
B39: Agencies - effective | C39: =Assumptions!$C$28*CHOOSE(Assumptions!$C$32,$C$35,$D$35,$E$35) | D39: entities | F39: Focus-6 subtotal x active breadth multiplier.
B40: Eng-heavy firms - effective | C40: =Assumptions!$C$29*CHOOSE(Assumptions!$C$32,$C$36,$D$36,$E$36) | D40: entities | F40: Focus-6 subtotal x active breadth multiplier.
B41: Mid-size firms - effective | C41: =Assumptions!$C$30*CHOOSE(Assumptions!$C$32,$C$37,$D$37,$E$37) | D41: entities | F41: Focus-6 subtotal x active breadth multiplier.
...

Sheet Build
B1: INVIRTUS - Revenue potential build (TAM / SAM / SOM)
B2: Bottoms-up: entities x %fit x tests/yr x net $/test, plus talent-DB stream. USD. All drivers live on Assumptions.
B4: A. Serviceable accounts (focus-6 = SAM geography)
B5: Segment | C5: Entities (focus-6) | D5: % fit | E5: Serviceable accts | F5: Tests/acct/yr | G5: ACV/acct ($) | H5: SAM value ($/yr)
B6: Tech recruiting agencies | C6: =Assumptions!$C$39 | D6: =Assumptions!$C$43 | E6: =C6*D6 | F6: =Assumptions!$C$66 | G6: =Assumptions!$C$77 | H6: =E6*G6
B7: Engineering-heavy firms | C7: =Assumptions!$C$40 | D7: =Assumptions!$C$44 | E7: =C7*D7 | F7: =Assumptions!$C$69 | G7: =Assumptions!$C$78 | H7: =E7*G7
B8: Mid-size structured-hiring firms | C8: =Assumptions!$C$41 | D8: =Assumptions!$C$45 | E8: =C8*D8 | F8: =Assumptions!$C$72 | G8: =Assumptions!$C$79 | H8: =E8*G8
B9: SAM (focus-6, serviceable today) | E9: =SUM(E6:E8) | H9: =SUM(H6:H8)
B11: B. TAM (all geos where product works, at full ACV)
B12: Global gross-up = focus-6 / (focus-6 share of global)
B13: Segment | C13: Global entities | D13: % fit | E13: Serviceable accts | F13: ACV/acct ($) | G13: TAM value ($/yr)
B14: Tech recruiting agencies | C14: =Assumptions!$C$39/Assumptions!$C$98 | D14: =Assumptions!$C$43 | E14: =C14*D14 | F14: =Assumptions!$C$77 | G14: =E14*F14
B15: Engineering-heavy firms | C15: =Assumptions!$C$40/Assumptions!$C$98 | D15: =Assumptions!$C$44 | E15: =C15*D15 | F15: =Assumptions!$C$78 | G15: =E15*F15
B16: Mid-size structured-hiring firms | C16: =Assumptions!$C$41/Assumptions!$C$98 | D16: =Assumptions!$C$45 | E16: =C16*D16 | F16: =Assumptions!$C$79 | G16: =E16*F16
B17: TAM (global prize, full ACV) | G17: =SUM(G14:G16)
B19: C. SOM (3-year reachable) - two routes side by side
B20: CHANNEL ROUTE (partner portfolio - see Assumptions sec.7)
B21: Channel base accounts (portfolio, y3) | E21: =Assumptions!$G$89
B22: Attach scalar | E22: =Assumptions!$C$90
B23: Active channel accounts | E23: =E21*E22
B24: Channel revenue ($/yr, retention-adj) | E24: =E23*Assumptions!$C$80*Assumptions!$C$97
B26: DIRECT ROUTE (self-serve + sales-led) | E26: Year 3
B27: Serviceable SAM accounts | E27: =Build!$E$9
B28: 3-yr penetration | E28: =Assumptions!$C$92
B29: Active direct accounts | E29: =E27*E28
B30: Direct revenue ($/yr, retention-adj) | E30: =Build!$H$9*E28*Assumptions!$C$97
B31: Funnel cross-check: implied paid/yr | E31: =Assumptions!$C$93*12*Assumptions!$C$94*Assumptions!$C$95
B33: SOM (Year 3 = Channel + Direct) | E33: =E24+E30
B35: D. Revenue potential by stream (assessments + talent-DB)
B36: Tier | C36: Assessment rev ($/yr) | D36: Tests run / yr | E36: Talent-DB rev ($/yr) | F36: TOTAL revenue potential ($/yr)
B37: Full opportunity (TAM) | C37: =Build!$G$17 | D37: =C37/Assumptions!$C$61 | E37: =D37*Assumptions!$C$104*Assumptions!$C$105 | F37: =C37+E37
B38: Serviceable today (SAM) | C38: =Build!$H$9 | D38: =C38/Assumptions!$C$61 | E38: =D38*Assumptions!$C$104*Assumptions!$C$105 | F38: =C38+E38
B39: 3-yr reachable (SOM) | C39: =Build!$E$33 | D39: =C39/Assumptions!$C$61 | E39: =D39*Assumptions!$C$104*Assumptions!$C$105 | F39: =C39+E39
B41: E. Value delivered (tests run -> hires -> bad-hire cost addressed)
B42: Ring | C42: Accounts | D42: Tests run / yr | E42: Hires supported / yr | F42: Bad-hire $ exposure influenced | G42: Mitigable value to buyers ($)
B43: SOM (yr 3) | C43: =(Build!$E$23+Build!$E$29) | D43: =C43*Assumptions!$C$75 | E43: =D43/Assumptions!$C$101 | F43: =E43*Assumptions!$C$100 | G43: =F43*Assumptions!$C$102
B45: Notes: (1) MECE - agencies and the firms they serve are distinct buyers; agency tests cover client roles, in-house tests cover own roles, no double count. (2) Channel (Manatal, global) and Direct (focus-6) may overlap modestly; treated as additive (slightly optimistic) and flagged. (3) Value-delivered ring is buyer-side: $ exposure influenced and mitigable value are NOT market size - they show the value pool Invirtus serves, against which the SOM revenue captured (~$2.2M) is a tiny slice. (4) Hires = gross placements assessment touches; agencies place for many clients, so per-account hires run high.

Sheet Sensitivity
B2: INVIRTUS - Sensitivity
B3: SOM (Yr3) response to the three swing inputs. Tables recompute the SOM chain live from the axis values; non-swung drivers pull from Assumptions.
B5: Table 1: SOM (Yr3) - Channel tests/account vs PAYG price/test
B6: tests/acct \ $/test | C6: 10 | D6: 12.5 | E6: 15 | F6: 17.5 | G6: 20
B7: 100 | C7: =Assumptions!$G$89*Assumptions!$C$90*($B7*((Assumptions!$C$56*C$6+Assumptions!$C$57*C$6*(1-Assumptions!$C$48)+Assumptions!$C$58*C$6*(1-Assumptions!$C$49)+Assumptions!$C$59*C$6*(1-Assumptions!$C$50))/(Assumptions!$C$56+Assumptions!$C$57+Assumptions!$C$58+Assumptions!$C$59)))*Assumptions!$C$97+(((Assumptions!$C$39*Assumptions!$C$43*((Assumptions!$C$64*Assumptions!$C$65*Assumptions!$C$63)*((Assumptions!$C$56*C$6+Assumptions!$C$57*C$6*(1-Assumptions!$C$48)+Assumptions!$C$58*C$6*(1-Assumptions!$C$49)+Assumptions!$C$59*C$6*(1-Assumptions!$C$50))/(Assumptions!$C$56+Assumptions!$C$57+Assumptions!$C$58+Assumptions!$C$59))))+(Assumptions!$C$40*Assumptions!$C$44*((Assumptions!$C$67*Assumptions!$C$68*Assumptions!$C$63)*((Assumptions!$C$56*C$6+Assumptions!$C$57*C$6*(1-Assumptions!$C$48)+Assumptions!$C$58*C$6*(1-Assumptions!$C$49)+Assumptions!$C$59*C$6*(1-Assumptions!$C$50))/(Assumptions!$C$56+Assumptions!$C$57+Assumptions!$C$58+Assumptions!$C$59))))+(Assumptions!$C$41*Assumptions!$C$45*((Assumptions!$C$70*Assumptions!$C$71*Assumptions!$C$63)*((Assumptions!$C$56*C$6+Assumptions!$C$57*C$6*(1-Assumptions!$C$48)+Assumptions!$C$58*C$6*(1-Assumptions!$C$49)+Assumptions!$C$59*C$6*(1-Assumptions!$C$50))/(Assumptions!$C$56+Assumptions!$C$57+Assumptions!$C$58+Assumptions!$C$59)))))*Assumptions!$C$92*Assumptions!$C$97) | D7: =Assumptions!$G$89*Assumptions!$C$90*($B7*((Assumptions!$C$56*D$6+Assumptions!$C$57*D$6*(1-Assumptions!$C$48)+Assumptions!$C$58*D$6*(1-Assumptions!$C$49)+Assumptions!$C$59*D$6*(1-Assumptions!$C$50))/(Assumptions!$C$56+Assumptions!$C$57+Assumptions!$C$58+Assumptions!$C$59)))*Assumptions!$C$97+(((Assumptions!$C$39*Assumptions!$C$43*((Assumptions!$C$64*Assumptions!$C$65*Assumptions!$C$63)*((Assumptions!$C$56*D$6+Assumptions!$C$57*D$6*(1-Assumptions!$C$48)+Assumptions!$C$58*D$6*(1-Assumptions!$C$49)+Assumptions!$C$59*D$6*(1-Assumptions!$C$50))/(Assumptions!$C$56+Assumptions!$C$57+Assumptions!$C$58+Assumptions!$C$59))))+(Assumptions!$C$40*Assumptions!$C$44*((Assumptions!$C$67*Assumptions!$C$68*Assumptions!$C$63)*((Assumptions!$C$56*D$6+Assumptions!$C$57*D$6*(1-Assumptions!$C$48)+Assumptions!$C$58*D$6*(1-Assumptions!$C$49)+Assumptions!$C$59*D$6*(1-Assumptions!$C$50))/(Assumptions!$C$56+Assumptions!$C$57+Assumptions!$C$58+Assumptions!$C$59))))+(Assumptions!$C$41*Assumptions!$C$45*((Assumptions!$C$70*Assumptions!$C$71*Assumptions!$C$63)*((Assumptions!$C$56*D$6+Assumptions!$C$57*D$6*(1-Assumptions!$C$48)+Assumptions!$C$58*D$6*(1-Assumptions!$C$49)+Assumptions!$C$59*D$6*(1-Assumptions!$C$50))/(Assumptions!$C$56+Assumptions!$C$57+Assumptions!$C$58+Assumptions!$C$59)))))*Assumptions!$C$92*Assumptions!$C$97) | E7: =Assumptions!$G$89*Assumptions!$C$90*($B7*((Assumptions!$C$56*E$6+Assumptions!$C$57*E$6*(1-Assumptions!$C$48)+Assumptions!$C$58*E$6*(1-Assumptions!$C$49)+Assumptions!$C$59*E$6*(1-Assumptions!$C$50))/(Assumptions!$C$56+Assumptions!$C$57+Assumptions!$C$58+Assumptions!$C$59)))*Assumptions!$C$97+(((Assumptions!$C$39*Assumptions!$C$43*((Assumptions!$C$64*Assumptions!$C$65*Assumptions!$C$63)*((Assumptions!$C$56*E$6+Assumptions!$C$57*E$6*(1-Assumptions!$C$48)+Assumptions!$C$58*E$6*(1-Assumptions!$C$49)+Assumptions!$C$59*E$6*(1-Assumptions!$C$50))/(Assumptions!$C$56+Assumptions!$C$57+Assumptions!$C$58+Assumptions!$C$59))))+(Assumptions!$C$40*Assumptions!$C$44*((Assumptions!$C$67*Assumptions!$C$68*Assumptions!$C$63)*((Assumptions!$C$56*E$6+Assumptions!$C$57*E$6*(1-Assumptions!$C$48)+Assumptions!$C$58*E$6*(1-Assumptions!$C$49)+Assumptions!$C$59*E$6*(1-Assumptions!$C$50))/(Assumptions!$C$56+Assumptions!$C$57+Assumptions!$C$58+Assumptions!$C$59))))+(Assumptions!$C$41*Assumptions!$C$45*((Assumptions!$C$70*Assumptions!$C$71*Assumptions!$C$63)*((Assumptions!$C$56*E$6+Assumptions!$C$57*E$6*(1-Assumptions!$C$48)+Assumptions!$C$58*E$6*(1-Assumptions!$C$49)+Assumptions!$C$59*E$6*(1-Assumptions!$C$50))/(Assumptions!$C$56+Assumptions!$C$57+Assumptions!$C$58+Assumptions!$C$59)))))*Assumptions!$C$92*Assumptions!$C$97) | F7: =Assumptions!$G$89*Assumptions!$C$90*($B7*((Assumptions!$C$56*F$6+Assumptions!$C$57*F$6*(1-Assumptions!$C$48)+Assumptions!$C$58*F$6*(1-Assumptions!$C$49)+Assumptions!$C$59*F$6*(1-Assumptions!$C$50))/(Assumptions!$C$56+Assumptions!$C$57+Assumptions!$C$58+Assumptions!$C$59)))*Assumptions!$C$97+(((Assumptions!$C$39*Assumptions!$C$43*((Assumptions!$C$64*Assumptions!$C$65*Assumptions!$C$63)*((Assumptions!$C$56*F$6+Assumptions!$C$57*F$6*(1-Assumptions!$C$48)+Assumptions!$C$58*F$6*(1-Assumptions!$C$49)+Assumptions!$C$59*F$6*(1-Assumptions!$C$50))/(Assumptions!$C$56+Assumptions!$C$57+Assumptions!$C$58+Assumptions!$C$59))))+(Assumptions!$C$40*Assumptions!$C$44*((Assumptions!$C$67*Assumptions!$C$68*Assumptions!$C$63)*((Assumptions!$C$56*F$6+Assumptions!$C$57*F$6*(1-Assumptions!$C$48)+Assumptions!$C$58*F$6*(1-Assumptions!$C$49)+Assumptions!$C$59*F$6*(1-Assumptions!$C$50))/(Assumptions!$C$56+Assumptions!$C$57+Assumptions!$C$58+Assumptions!$C$59))))+(Assumptions!$C$41*Assumptions!$C$45*((Assumptions!$C$70*Assumptions!$C$71*Assumptions!$C$63)*((Assumptions!$C$56*F$6+Assumptions!$C$57*F$6*(1-Assumptions!$C$48)+Assumptions!$C$58*F$6*(1-Assumptions!$C$49)+Assumptions!$C$59*F$6*(1-Assumptions!$C$50))/(Assumptions!$C$56+Assumptions!$C$57+Assumptions!$C$58+Assumptions!$C$59)))))*Assumptions!$C$92*Assumptions!$C$97) | G7: =Assumptions!$G$89*Assumptions!$C$90*($B7*((Assumptions!$C$56*G$6+Assumptions!$C$57*G$6*(1-Assumptions!$C$48)+Assumptions!$C$58*G$6*(1-Assumptions!$C$49)+Assumptions!$C$59*G$6*(1-Assumptions!$C$50))/(Assumptions!$C$56+Assumptions!$C$57+Assumptions!$C$58+Assumptions!$C$59)))*Assumptions!$C$97+(((Assumptions!$C$39*Assumptions!$C$43*((Assumptions!$C$64*Assumptions!$C$65*Assumptions!$C$63)*((Assumptions!$C$56*G$6+Assumptions!$C$57*G$6*(1-Assumptions!$C$48)+Assumptions!$C$58*G$6*(1-Assumptions!$C$49)+Assumptions!$C$59*G$6*(1-Assumptions!$C$50))/(Assumptions!$C$56+Assumptions!$C$57+Assumptions!$C$58+Assumptions!$C$59))))+(Assumptions!$C$40*Assumptions!$C$44*((Assumptions!$C$67*Assumptions!$C$68*Assumptions!$C$63)*((Assumptions!$C$56*G$6+Assumptions!$C$57*G$6*(1-Assumptions!$C$48)+Assumptions!$C$58*G$6*(1-Assumptions!$C$49)+Assumptions!$C$59*G$6*(1-Assumptions!$C$50))/(Assumptions!$C$56+Assumptions!$C$57+Assumptions!$C$58+Assumptions!$C$59))))+(Assumptions!$C$41*Assumptions!$C$45*((Assumptions!$C$70*Assumptions!$C$71*Assumptions!$C$63)*((Assumptions!$C$56*G$6+Assumptions!$C$57*G$6*(1-Assumptions!$C$48)+Assumptions!$C$58*G$6*(1-Assumptions!$C$49)+Assumptions!$C$59*G$6*(1-Assumptions!$C$50))/(Assumptions!$C$56+Assumptions!$C$57+Assumptions!$C$58+Assumptions!$C$59)))))*Assumptions!$C$92*Assumptions!$C$97)
B8: 150 | C8: =Assumptions!$G$89*Assumptions!$C$90*($B8*((Assumptions!$C$56*C$6+Assumptions!$C$57*C$6*(1-Assumptions!$C$48)+Assumptions!$C$58*C$6*(1-Assumptions!$C$49)+Assumptions!$C$59*C$6*(1-Assumptions!$C$50))/(Assumptions!$C$56+Assumptions!$C$57+Assumptions!$C$58+Assumptions!$C$59)))*Assumptions!$C$97+(((Assumptions!$C$39*Assumptions!$C$43*((Assumptions!$C$64*Assumptions!$C$65*Assumptions!$C$63)*((Assumptions!$C$56*C$6+Assumptions!$C$57*C$6*(1-Assumptions!$C$48)+Assumptions!$C$58*C$6*(1-Assumptions!$C$49)+Assumptions!$C$59*C$6*(1-Assumptions!$C$50))/(Assumptions!$C$56+Assumptions!$C$57+Assumptions!$C$58+Assumptions!$C$59))))+(Assumptions!$C$40*Assumptions!$C$44*((Assumptions!$C$67*Assumptions!$C$68*Assumptions!$C$63)*((Assumptions!$C$56*C$6+Assumptions!$C$57*C$6*(1-Assumptions!$C$48)+Assumptions!$C$58*C$6*(1-Assumptions!$C$49)+Assumptions!$C$59*C$6*(1-Assumptions!$C$50))/(Assumptions!$C$56+Assumptions!$C$57+Assumptions!$C$58+Assumptions!$C$59))))+(Assumptions!$C$41*Assumptions!$C$45*((Assumptions!$C$70*Assumptions!$C$71*Assumptions!$C$63)*((Assumptions!$C$56*C$6+Assumptions!$C$57*C$6*(1-Assumptions!$C$48)+Assumptions!$C$58*C$6*(1-Assumptions!$C$49)+Assumptions!$C$59*C$6*(1-Assumptions!$C$50))/(Assumptions!$C$56+Assumptions!$C$57+Assumptions!$C$58+Assumptions!$C$59)))))*Assumptions!$C$92*Assumptions!$C$97) | D8: =Assumptions!$G$89*Assumptions!$C$90*($B8*((Assumptions!$C$56*D$6+Assumptions!$C$57*D$6*(1-Assumptions!$C$48)+Assumptions!$C$58*D$6*(1-Assumptions!$C$49)+Assumptions!$C$59*D$6*(1-Assumptions!$C$50))/(Assumptions!$C$56+Assumptions!$C$57+Assumptions!$C$58+Assumptions!$C$59)))*Assumptions!$C$97+(((Assumptions!$C$39*Assumptions!$C$43*((Assumptions!$C$64*Assumptions!$C$65*Assumptions!$C$63)*((Assumptions!$C$56*D$6+Assumptions!$C$57*D$6*(1-Assumptions!$C$48)+Assumptions!$C$58*D$6*(1-Assumptions!$C$49)+Assumptions!$C$59*D$6*(1-Assumptions!$C$50))/(Assumptions!$C$56+Assumptions!$C$57+Assumptions!$C$58+Assumptions!$C$59))))+(Assumptions!$C$40*Assumptions!$C$44*((Assumptions!$C$67*Assumptions!$C$68*Assumptions!$C$63)*((Assumptions!$C$56*D$6+Assumptions!$C$57*D$6*(1-Assumptions!$C$48)+Assumptions!$C$58*D$6*(1-Assumptions!$C$49)+Assumptions!$C$59*D$6*(1-Assumptions!$C$50))/(Assumptions!$C$56+Assumptions!$C$57+Assumptions!$C$58+Assumptions!$C$59))))+(Assumptions!$C$41*Assumptions!$C$45*((Assumptions!$C$70*Assumptions!$C$71*Assumptions!$C$63)*((Assumptions!$C$56*D$6+Assumptions!$C$57*D$6*(1-Assumptions!$C$48)+Assumptions!$C$58*D$6*(1-Assumptions!$C$49)+Assumptions!$C$59*D$6*(1-Assumptions!$C$50))/(Assumptions!$C$56+Assumptions!$C$57+Assumptions!$C$58+Assumptions!$C$59)))))*Assumptions!$C$92*Assumptions!$C$97) | E8: =Assumptions!$G$89*Assumptions!$C$90*($B8*((Assumptions!$C$56*E$6+Assumptions!$C$57*E$6*(1-Assumptions!$C$48)+Assumptions!$C$58*E$6*(1-Assumptions!$C$49)+Assumptions!$C$59*E$6*(1-Assumptions!$C$50))/(Assumptions!$C$56+Assumptions!$C$57+Assumptions!$C$58+Assumptions!$C$59)))*Assumptions!$C$97+(((Assumptions!$C$39*Assumptions!$C$43*((Assumptions!$C$64*Assumptions!$C$65*Assumptions!$C$63)*((Assumptions!$C$56*E$6+Assumptions!$C$57*E$6*(1-Assumptions!$C$48)+Assumptions!$C$58*E$6*(1-Assumptions!$C$49)+Assumptions!$C$59*E$6*(1-Assumptions!$C$50))/(Assumptions!$C$56+Assumptions!$C$57+Assumptions!$C$58+Assumptions!$C$59))))+(Assumptions!$C$40*Assumptions!$C$44*((Assumptions!$C$67*Assumptions!$C$68*Assumptions!$C$63)*((Assumptions!$C$56*E$6+Assumptions!$C$57*E$6*(1-Assumptions!$C$48)+Assumptions!$C$58*E$6*(1-Assumptions!$C$49)+Assumptions!$C$59*E$6*(1-Assumptions!$C$50))/(Assumptions!$C$56+Assumptions!$C$57+Assumptions!$C$58+Assumptions!$C$59))))+(Assumptions!$C$41*Assumptions!$C$45*((Assumptions!$C$70*Assumptions!$C$71*Assumptions!$C$63)*((Assumptions!$C$56*E$6+Assumptions!$C$57*E$6*(1-Assumptions!$C$48)+Assumptions!$C$58*E$6*(1-Assumptions!$C$49)+Assumptions!$C$59*E$6*(1-Assumptions!$C$50))/(Assumptions!$C$56+Assumptions!$C$57+Assumptions!$C$58+Assumptions!$C$59)))))*Assumptions!$C$92*Assumptions!$C$97) | F8: =Assumptions!$G$89*Assumptions!$C$90*($B8*((Assumptions!$C$56*F$6+Assumptions!$C$57*F$6*(1-Assumptions!$C$48)+Assumptions!$C$58*F$6*(1-Assumptions!$C$49)+Assumptions!$C$59*F$6*(1-Assumptions!$C$50))/(Assumptions!$C$56+Assumptions!$C$57+Assumptions!$C$58+Assumptions!$C$59)))*Assumptions!$C$97+(((Assumptions!$C$39*Assumptions!$C$43*((Assumptions!$C$64*Assumptions!$C$65*Assumptions!$C$63)*((Assumptions!$C$56*F$6+Assumptions!$C$57*F$6*(1-Assumptions!$C$48)+Assumptions!$C$58*F$6*(1-Assumptions!$C$49)+Assumptions!$C$59*F$6*(1-Assumptions!$C$50))/(Assumptions!$C$56+Assumptions!$C$57+Assumptions!$C$58+Assumptions!$C$59))))+(Assumptions!$C$40*Assumptions!$C$44*((Assumptions!$C$67*Assumptions!$C$68*Assumptions!$C$63)*((Assumptions!$C$56*F$6+Assumptions!$C$57*F$6*(1-Assumptions!$C$48)+Assumptions!$C$58*F$6*(1-Assumptions!$C$49)+Assumptions!$C$59*F$6*(1-Assumptions!$C$50))/(Assumptions!$C$56+Assumptions!$C$57+Assumptions!$C$58+Assumptions!$C$59))))+(Assumptions!$C$41*Assumptions!$C$45*((Assumptions!$C$70*Assumptions!$C$71*Assumptions!$C$63)*((Assumptions!$C$56*F$6+Assumptions!$C$57*F$6*(1-Assumptions!$C$48)+Assumptions!$C$58*F$6*(1-Assumptions!$C$49)+Assumptions!$C$59*F$6*(1-Assumptions!$C$50))/(Assumptions!$C$56+Assumptions!$C$57+Assumptions!$C$58+Assumptions!$C$59)))))*Assumptions!$C$92*Assumptions!$C$97) | G8: =Assumptions!$G$89*Assumptions!$C$90*($B8*((Assumptions!$C$56*G$6+Assumptions!$C$57*G$6*(1-Assumptions!$C$48)+Assumptions!$C$58*G$6*(1-Assumptions!$C$49)+Assumptions!$C$59*G$6*(1-Assumptions!$C$50))/(Assumptions!$C$56+Assumptions!$C$57+Assumptions!$C$58+Assumptions!$C$59)))*Assumptions!$C$97+(((Assumptions!$C$39*Assumptions!$C$43*((Assumptions!$C$64*Assumptions!$C$65*Assumptions!$C$63)*((Assumptions!$C$56*G$6+Assumptions!$C$57*G$6*(1-Assumptions!$C$48)+Assumptions!$C$58*G$6*(1-Assumptions!$C$49)+Assumptions!$C$59*G$6*(1-Assumptions!$C$50))/(Assumptions!$C$56+Assumptions!$C$57+Assumptions!$C$58+Assumptions!$C$59))))+(Assumptions!$C$40*Assumptions!$C$44*((Assumptions!$C$67*Assumptions!$C$68*Assumptions!$C$63)*((Assumptions!$C$56*G$6+Assumptions!$C$57*G$6*(1-Assumptions!$C$48)+Assumptions!$C$58*G$6*(1-Assumptions!$C$49)+Assumptions!$C$59*G$6*(1-Assumptions!$C$50))/(Assumptions!$C$56+Assumptions!$C$57+Assumptions!$C$58+Assumptions!$C$59))))+(Assumptions!$C$41*Assumptions!$C$45*((Assumptions!$C$70*Assumptions!$C$71*Assumptions!$C$63)*((Assumptions!$C$56*G$6+Assumptions!$C$57*G$6*(1-Assumptions!$C$48)+Assumptions!$C$58*G$6*(1-Assumptions!$C$49)+Assumptions!$C$59*G$6*(1-Assumptions!$C$50))/(Assumptions!$C$56+Assumptions!$C$57+Assumptions!$C$58+Assumptions!$C$59)))))*Assumptions!$C$92*Assumptions!$C$97)
B9: 200 | C9: =Assumptions!$G$89*Assumptions!$C$90*($B9*((Assumptions!$C$56*C$6+Assumptions!$C$57*C$6*(1-Assumptions!$C$48)+Assumptions!$C$58*C$6*(1-Assumptions!$C$49)+Assumptions!$C$59*C$6*(1-Assumptions!$C$50))/(Assumptions!$C$56+Assumptions!$C$57+Assumptions!$C$58+Assumptions!$C$59)))*Assumptions!$C$97+(((Assumptions!$C$39*Assumptions!$C$43*((Assumptions!$C$64*Assumptions!$C$65*Assumptions!$C$63)*((Assumptions!$C$56*C$6+Assumptions!$C$57*C$6*(1-Assumptions!$C$48)+Assumptions!$C$58*C$6*(1-Assumptions!$C$49)+Assumptions!$C$59*C$6*(1-Assumptions!$C$50))/(Assumptions!$C$56+Assumptions!$C$57+Assumptions!$C$58+Assumptions!$C$59))))+(Assumptions!$C$40*Assumptions!$C$44*((Assumptions!$C$67*Assumptions!$C$68*Assumptions!$C$63)*((Assumptions!$C$56*C$6+Assumptions!$C$57*C$6*(1-Assumptions!$C$48)+Assumptions!$C$58*C$6*(1-Assumptions!$C$49)+Assumptions!$C$59*C$6*(1-Assumptions!$C$50))/(Assumptions!$C$56+Assumptions!$C$57+Assumptions!$C$58+Assumptions!$C$59))))+(Assumptions!$C$41*Assumptions!$C$45*((Assumptions!$C$70*Assumptions!$C$71*Assumptions!$C$63)*((Assumptions!$C$56*C$6+Assumptions!$C$57*C$6*(1-Assumptions!$C$48)+Assumptions!$C$58*C$6*(1-Assumptions!$C$49)+Assumptions!$C$59*C$6*(1-Assumptions!$C$50))/(Assumptions!$C$56+Assumptions!$C$57+Assumptions!$C$58+Assumptions!$C$59)))))*Assumptions!$C$92*Assumptions!$C$97) | D9: =Assumptions!$G$89*Assumptions!$C$90*($B9*((Assumptions!$C$56*D$6+Assumptions!$C$57*D$6*(1-Assumptions!$C$48)+Assumptions!$C$58*D$6*(1-Assumptions!$C$49)+Assumptions!$C$59*D$6*(1-Assumptions!$C$50))/(Assumptions!$C$56+Assumptions!$C$57+Assumptions!$C$58+Assumptions!$C$59)))*Assumptions!$C$97+(((Assumptions!$C$39*Assumptions!$C$43*((Assumptions!$C$64*Assumptions!$C$65*Assumptions!$C$63)*((Assumptions!$C$56*D$6+Assumptions!$C$57*D$6*(1-Assumptions!$C$48)+Assumptions!$C$58*D$6*(1-Assumptions!$C$49)+Assumptions!$C$59*D$6*(1-Assumptions!$C$50))/(Assumptions!$C$56+Assumptions!$C$57+Assumptions!$C$58+Assumptions!$C$59))))+(Assumptions!$C$40*Assumptions!$C$44*((Assumptions!$C$67*Assumptions!$C$68*Assumptions!$C$63)*((Assumptions!$C$56*D$6+Assumptions!$C$57*D$6*(1-Assumptions!$C$48)+Assumptions!$C$58*D$6*(1-Assumptions!$C$49)+Assumptions!$C$59*D$6*(1-Assumptions!$C$50))/(Assumptions!$C$56+Assumptions!$C$57+Assumptions!$C$58+Assumptions!$C$59))))+(Assumptions!$C$41*Assumptions!$C$45*((Assumptions!$C$70*Assumptions!$C$71*Assumptions!$C$63)*((Assumptions!$C$56*D$6+Assumptions!$C$57*D$6*(1-Assumptions!$C$48)+Assumptions!$C$58*D$6*(1-Assumptions!$C$49)+Assumptions!$C$59*D$6*(1-Assumptions!$C$50))/(Assumptions!$C$56+Assumptions!$C$57+Assumptions!$C$58+Assumptions!$C$59)))))*Assumptions!$C$92*Assumptions!$C$97) | E9: =Assumptions!$G$89*Assumptions!$C$90*($B9*((Assumptions!$C$56*E$6+Assumptions!$C$57*E$6*(1-Assumptions!$C$48)+Assumptions!$C$58*E$6*(1-Assumptions!$C$49)+Assumptions!$C$59*E$6*(1-Assumptions!$C$50))/(Assumptions!$C$56+Assumptions!$C$57+Assumptions!$C$58+Assumptions!$C$59)))*Assumptions!$C$97+(((Assumptions!$C$39*Assumptions!$C$43*((Assumptions!$C$64*Assumptions!$C$65*Assumptions!$C$63)*((Assumptions!$C$56*E$6+Assumptions!$C$57*E$6*(1-Assumptions!$C$48)+Assumptions!$C$58*E$6*(1-Assumptions!$C$49)+Assumptions!$C$59*E$6*(1-Assumptions!$C$50))/(Assumptions!$C$56+Assumptions!$C$57+Assumptions!$C$58+Assumptions!$C$59))))+(Assumptions!$C$40*Assumptions!$C$44*((Assumptions!$C$67*Assumptions!$C$68*Assumptions!$C$63)*((Assumptions!$C$56*E$6+Assumptions!$C$57*E$6*(1-Assumptions!$C$48)+Assumptions!$C$58*E$6*(1-Assumptions!$C$49)+Assumptions!$C$59*E$6*(1-Assumptions!$C$50))/(Assumptions!$C$56+Assumptions!$C$57+Assumptions!$C$58+Assumptions!$C$59))))+(Assumptions!$C$41*Assumptions!$C$45*((Assumptions!$C$70*Assumptions!$C$71*Assumptions!$C$63)*((Assumptions!$C$56*E$6+Assumptions!$C$57*E$6*(1-Assumptions!$C$48)+Assumptions!$C$58*E$6*(1-Assumptions!$C$49)+Assumptions!$C$59*E$6*(1-Assumptions!$C$50))/(Assumptions!$C$56+Assumptions!$C$57+Assumptions!$C$58+Assumptions!$C$59)))))*Assumptions!$C$92*Assumptions!$C$97) | F9: =Assumptions!$G$89*Assumptions!$C$90*($B9*((Assumptions!$C$56*F$6+Assumptions!$C$57*F$6*(1-Assumptions!$C$48)+Assumptions!$C$58*F$6*(1-Assumptions!$C$49)+Assumptions!$C$59*F$6*(1-Assumptions!$C$50))/(Assumptions!$C$56+Assumptions!$C$57+Assumptions!$C$58+Assumptions!$C$59)))*Assumptions!$C$97+(((Assumptions!$C$39*Assumptions!$C$43*((Assumptions!$C$64*Assumptions!$C$65*Assumptions!$C$63)*((Assumptions!$C$56*F$6+Assumptions!$C$57*F$6*(1-Assumptions!$C$48)+Assumptions!$C$58*F$6*(1-Assumptions!$C$49)+Assumptions!$C$59*F$6*(1-Assumptions!$C$50))/(Assumptions!$C$56+Assumptions!$C$57+Assumptions!$C$58+Assumptions!$C$59))))+(Assumptions!$C$40*Assumptions!$C$44*((Assumptions!$C$67*Assumptions!$C$68*Assumptions!$C$63)*((Assumptions!$C$56*F$6+Assumptions!$C$57*F$6*(1-Assumptions!$C$48)+Assumptions!$C$58*F$6*(1-Assumptions!$C$49)+Assumptions!$C$59*F$6*(1-Assumptions!$C$50))/(Assumptions!$C$56+Assumptions!$C$57+Assumptions!$C$58+Assumptions!$C$59))))+(Assumptions!$C$41*Assumptions!$C$45*((Assumptions!$C$70*Assumptions!$C$71*Assumptions!$C$63)*((Assumptions!$C$56*F$6+Assumptions!$C$57*F$6*(1-Assumptions!$C$48)+Assumptions!$C$58*F$6*(1-Assumptions!$C$49)+Assumptions!$C$59*F$6*(1-Assumptions!$C$50))/(Assumptions!$C$56+Assumptions!$C$57+Assumptions!$C$58+Assumptions!$C$59)))))*Assumptions!$C$92*Assumptions!$C$97) | G9: =Assumptions!$G$89*Assumptions!$C$90*($B9*((Assumptions!$C$56*G$6+Assumptions!$C$57*G$6*(1-Assumptions!$C$48)+Assumptions!$C$58*G$6*(1-Assumptions!$C$49)+Assumptions!$C$59*G$6*(1-Assumptions!$C$50))/(Assumptions!$C$56+Assumptions!$C$57+Assumptions!$C$58+Assumptions!$C$59)))*Assumptions!$C$97+(((Assumptions!$C$39*Assumptions!$C$43*((Assumptions!$C$64*Assumptions!$C$65*Assumptions!$C$63)*((Assumptions!$C$56*G$6+Assumptions!$C$57*G$6*(1-Assumptions!$C$48)+Assumptions!$C$58*G$6*(1-Assumptions!$C$49)+Assumptions!$C$59*G$6*(1-Assumptions!$C$50))/(Assumptions!$C$56+Assumptions!$C$57+Assumptions!$C$58+Assumptions!$C$59))))+(Assumptions!$C$40*Assumptions!$C$44*((Assumptions!$C$67*Assumptions!$C$68*Assumptions!$C$63)*((Assumptions!$C$56*G$6+Assumptions!$C$57*G$6*(1-Assumptions!$C$48)+Assumptions!$C$58*G$6*(1-Assumptions!$C$49)+Assumptions!$C$59*G$6*(1-Assumptions!$C$50))/(Assumptions!$C$56+Assumptions!$C$57+Assumptions!$C$58+Assumptions!$C$59))))+(Assumptions!$C$41*Assumptions!$C$45*((Assumptions!$C$70*Assumptions!$C$71*Assumptions!$C$63)*((Assumptions!$C$56*G$6+Assumptions!$C$57*G$6*(1-Assumptions!$C$48)+Assumptions!$C$58*G$6*(1-Assumptions!$C$49)+Assumptions!$C$59*G$6*(1-Assumptions!$C$50))/(Assumptions!$C$56+Assumptions!$C$57+Assumptions!$C$58+Assumptions!$C$59)))))*Assumptions!$C$92*Assumptions!$C$97)
B10: 250 | C10: =Assumptions!$G$89*Assumptions!$C$90*($B10*((Assumptions!$C$56*C$6+Assumptions!$C$57*C$6*(1-Assumptions!$C$48)+Assumptions!$C$58*C$6*(1-Assumptions!$C$49)+Assumptions!$C$59*C$6*(1-Assumptions!$C$50))/(Assumptions!$C$56+Assumptions!$C$57+Assumptions!$C$58+Assumptions!$C$59)))*Assumptions!$C$97+(((Assumptions!$C$39*Assumptions!$C$43*((Assumptions!$C$64*Assumptions!$C$65*Assumptions!$C$63)*((Assumptions!$C$56*C$6+Assumptions!$C$57*C$6*(1-Assumptions!$C$48)+Assumptions!$C$58*C$6*(1-Assumptions!$C$49)+Assumptions!$C$59*C$6*(1-Assumptions!$C$50))/(Assumptions!$C$56+Assumptions!$C$57+Assumptions!$C$58+Assumptions!$C$59))))+(Assumptions!$C$40*Assumptions!$C$44*((Assumptions!$C$67*Assumptions!$C$68*Assumptions!$C$63)*((Assumptions!$C$56*C$6+Assumptions!$C$57*C$6*(1-Assumptions!$C$48)+Assumptions!$C$58*C$6*(1-Assumptions!$C$49)+Assumptions!$C$59*C$6*(1-Assumptions!$C$50))/(Assumptions!$C$56+Assumptions!$C$57+Assumptions!$C$58+Assumptions!$C$59))))+(Assumptions!$C$41*Assumptions!$C$45*((Assumptions!$C$70*Assumptions!$C$71*Assumptions!$C$63)*((Assumptions!$C$56*C$6+Assumptions!$C$57*C$6*(1-Assumptions!$C$48)+Assumptions!$C$58*C$6*(1-Assumptions!$C$49)+Assumptions!$C$59*C$6*(1-Assumptions!$C$50))/(Assumptions!$C$56+Assumptions!$C$57+Assumptions!$C$58+Assumptions!$C$59)))))*Assumptions!$C$92*Assumptions!$C$97) | D10: =Assumptions!$G$89*Assumptions!$C$90*($B10*((Assumptions!$C$56*D$6+Assumptions!$C$57*D$6*(1-Assumptions!$C$48)+Assumptions!$C$58*D$6*(1-Assumptions!$C$49)+Assumptions!$C$59*D$6*(1-Assumptions!$C$50))/(Assumptions!$C$56+Assumptions!$C$57+Assumptions!$C$58+Assumptions!$C$59)))*Assumptions!$C$97+(((Assumptions!$C$39*Assumptions!$C$43*((Assumptions!$C$64*Assumptions!$C$65*Assumptions!$C$63)*((Assumptions!$C$56*D$6+Assumptions!$C$57*D$6*(1-Assumptions!$C$48)+Assumptions!$C$58*D$6*(1-Assumptions!$C$49)+Assumptions!$C$59*D$6*(1-Assumptions!$C$50))/(Assumptions!$C$56+Assumptions!$C$57+Assumptions!$C$58+Assumptions!$C$59))))+(Assumptions!$C$40*Assumptions!$C$44*((Assumptions!$C$67*Assumptions!$C$68*Assumptions!$C$63)*((Assumptions!$C$56*D$6+Assumptions!$C$57*D$6*(1-Assumptions!$C$48)+Assumptions!$C$58*D$6*(1-Assumptions!$C$49)+Assumptions!$C$59*D$6*(1-Assumptions!$C$50))/(Assumptions!$C$56+Assumptions!$C$57+Assumptions!$C$58+Assumptions!$C$59))))+(Assumptions!$C$41*Assumptions!$C$45*((Assumptions!$C$70*Assumptions!$C$71*Assumptions!$C$63)*((Assumptions!$C$56*D$6+Assumptions!$C$57*D$6*(1-Assumptions!$C$48)+Assumptions!$C$58*D$6*(1-Assumptions!$C$49)+Assumptions!$C$59*D$6*(1-Assumptions!$C$50))/(Assumptions!$C$56+Assumptions!$C$57+Assumptions!$C$58+Assumptions!$C$59)))))*Assumptions!$C$92*Assumptions!$C$97) | E10: =Assumptions!$G$89*Assumptions!$C$90*($B10*((Assumptions!$C$56*E$6+Assumptions!$C$57*E$6*(1-Assumptions!$C$48)+Assumptions!$C$58*E$6*(1-Assumptions!$C$49)+Assumptions!$C$59*E$6*(1-Assumptions!$C$50))/(Assumptions!$C$56+Assumptions!$C$57+Assumptions!$C$58+Assumptions!$C$59)))*Assumptions!$C$97+(((Assumptions!$C$39*Assumptions!$C$43*((Assumptions!$C$64*Assumptions!$C$65*Assumptions!$C$63)*((Assumptions!$C$56*E$6+Assumptions!$C$57*E$6*(1-Assumptions!$C$48)+Assumptions!$C$58*E$6*(1-Assumptions!$C$49)+Assumptions!$C$59*E$6*(1-Assumptions!$C$50))/(Assumptions!$C$56+Assumptions!$C$57+Assumptions!$C$58+Assumptions!$C$59))))+(Assumptions!$C$40*Assumptions!$C$44*((Assumptions!$C$67*Assumptions!$C$68*Assumptions!$C$63)*((Assumptions!$C$56*E$6+Assumptions!$C$57*E$6*(1-Assumptions!$C$48)+Assumptions!$C$58*E$6*(1-Assumptions!$C$49)+Assumptions!$C$59*E$6*(1-Assumptions!$C$50))/(Assumptions!$C$56+Assumptions!$C$57+Assumptions!$C$58+Assumptions!$C$59))))+(Assumptions!$C$41*Assumptions!$C$45*((Assumptions!$C$70*Assumptions!$C$71*Assumptions!$C$63)*((Assumptions!$C$56*E$6+Assumptions!$C$57*E$6*(1-Assumptions!$C$48)+Assumptions!$C$58*E$6*(1-Assumptions!$C$49)+Assumptions!$C$59*E$6*(1-Assumptions!$C$50))/(Assumptions!$C$56+Assumptions!$C$57+Assumptions!$C$58+Assumptions!$C$59)))))*Assumptions!$C$92*Assumptions!$C$97) | F10: =Assumptions!$G$89*Assumptions!$C$90*($B10*((Assumptions!$C$56*F$6+Assumptions!$C$57*F$6*(1-Assumptions!$C$48)+Assumptions!$C$58*F$6*(1-Assumptions!$C$49)+Assumptions!$C$59*F$6*(1-Assumptions!$C$50))/(Assumptions!$C$56+Assumptions!$C$57+Assumptions!$C$58+Assumptions!$C$59)))*Assumptions!$C$97+(((Assumptions!$C$39*Assumptions!$C$43*((Assumptions!$C$64*Assumptions!$C$65*Assumptions!$C$63)*((Assumptions!$C$56*F$6+Assumptions!$C$57*F$6*(1-Assumptions!$C$48)+Assumptions!$C$58*F$6*(1-Assumptions!$C$49)+Assumptions!$C$59*F$6*(1-Assumptions!$C$50))/(Assumptions!$C$56+Assumptions!$C$57+Assumptions!$C$58+Assumptions!$C$59))))+(Assumptions!$C$40*Assumptions!$C$44*((Assumptions!$C$67*Assumptions!$C$68*Assumptions!$C$63)*((Assumptions!$C$56*F$6+Assumptions!$C$57*F$6*(1-Assumptions!$C$48)+Assumptions!$C$58*F$6*(1-Assumptions!$C$49)+Assumptions!$C$59*F$6*(1-Assumptions!$C$50))/(Assumptions!$C$56+Assumptions!$C$57+Assumptions!$C$58+Assumptions!$C$59))))+(Assumptions!$C$41*Assumptions!$C$45*((Assumptions!$C$70*Assumptions!$C$71*Assumptions!$C$63)*((Assumptions!$C$56*F$6+Assumptions!$C$57*F$6*(1-Assumptions!$C$48)+Assumptions!$C$58*F$6*(1-Assumptions!$C$49)+Assumptions!$C$59*F$6*(1-Assumptions!$C$50))/(Assumptions!$C$56+Assumptions!$C$57+Assumptions!$C$58+Assumptions!$C$59)))))*Assumptions!$C$92*Assumptions!$C$97) | G10: =Assumptions!$G$89*Assumptions!$C$90*($B10*((Assumptions!$C$56*G$6+Assumptions!$C$57*G$6*(1-Assumptions!$C$48)+Assumptions!$C$58*G$6*(1-Assumptions!$C$49)+Assumptions!$C$59*G$6*(1-Assumptions!$C$50))/(Assumptions!$C$56+Assumptions!$C$57+Assumptions!$C$58+Assumptions!$C$59)))*Assumptions!$C$97+(((Assumptions!$C$39*Assumptions!$C$43*((Assumptions!$C$64*Assumptions!$C$65*Assumptions!$C$63)*((Assumptions!$C$56*G$6+Assumptions!$C$57*G$6*(1-Assumptions!$C$48)+Assumptions!$C$58*G$6*(1-Assumptions!$C$49)+Assumptions!$C$59*G$6*(1-Assumptions!$C$50))/(Assumptions!$C$56+Assumptions!$C$57+Assumptions!$C$58+Assumptions!$C$59))))+(Assumptions!$C$40*Assumptions!$C$44*((Assumptions!$C$67*Assumptions!$C$68*Assumptions!$C$63)*((Assumptions!$C$56*G$6+Assumptions!$C$57*G$6*(1-Assumptions!$C$48)+Assumptions!$C$58*G$6*(1-Assumptions!$C$49)+Assumptions!$C$59*G$6*(1-Assumptions!$C$50))/(Assumptions!$C$56+Assumptions!$C$57+Assumptions!$C$58+Assumptions!$C$59))))+(Assumptions!$C$41*Assumptions!$C$45*((Assumptions!$C$70*Assumptions!$C$71*Assumptions!$C$63)*((Assumptions!$C$56*G$6+Assumptions!$C$57*G$6*(1-Assumptions!$C$48)+Assumptions!$C$58*G$6*(1-Assumptions!$C$49)+Assumptions!$C$59*G$6*(1-Assumptions!$C$50))/(Assumptions!$C$56+Assumptions!$C$57+Assumptions!$C$58+Assumptions!$C$59)))))*Assumptions!$C$92*Assumptions!$C$97)
B11: 300 | C11: =Assumptions!$G$89*Assumptions!$C$90*($B11*((Assumptions!$C$56*C$6+Assumptions!$C$57*C$6*(1-Assumptions!$C$48)+Assumptions!$C$58*C$6*(1-Assumptions!$C$49)+Assumptions!$C$59*C$6*(1-Assumptions!$C$50))/(Assumptions!$C$56+Assumptions!$C$57+Assumptions!$C$58+Assumptions!$C$59)))*Assumptions!$C$97+(((Assumptions!$C$39*Assumptions!$C$43*((Assumptions!$C$64*Assumptions!$C$65*Assumptions!$C$63)*((Assumptions!$C$56*C$6+Assumptions!$C$57*C$6*(1-Assumptions!$C$48)+Assumptions!$C$58*C$6*(1-Assumptions!$C$49)+Assumptions!$C$59*C$6*(1-Assumptions!$C$50))/(Assumptions!$C$56+Assumptions!$C$57+Assumptions!$C$58+Assumptions!$C$59))))+(Assumptions!$C$40*Assumptions!$C$44*((Assumptions!$C$67*Assumptions!$C$68*Assumptions!$C$63)*((Assumptions!$C$56*C$6+Assumptions!$C$57*C$6*(1-Assumptions!$C$48)+Assumptions!$C$58*C$6*(1-Assumptions!$C$49)+Assumptions!$C$59*C$6*(1-Assumptions!$C$50))/(Assumptions!$C$56+Assumptions!$C$57+Assumptions!$C$58+Assumptions!$C$59))))+(Assumptions!$C$41*Assumptions!$C$45*((Assumptions!$C$70*Assumptions!$C$71*Assumptions!$C$63)*((Assumptions!$C$56*C$6+Assumptions!$C$57*C$6*(1-Assumptions!$C$48)+Assumptions!$C$58*C$6*(1-Assumptions!$C$49)+Assumptions!$C$59*C$6*(1-Assumptions!$C$50))/(Assumptions!$C$56+Assumptions!$C$57+Assumptions!$C$58+Assumptions!$C$59)))))*Assumptions!$C$92*Assumptions!$C$97) | D11: =Assumptions!$G$89*Assumptions!$C$90*($B11*((Assumptions!$C$56*D$6+Assumptions!$C$57*D$6*(1-Assumptions!$C$48)+Assumptions!$C$58*D$6*(1-Assumptions!$C$49)+Assumptions!$C$59*D$6*(1-Assumptions!$C$50))/(Assumptions!$C$56+Assumptions!$C$57+Assumptions!$C$58+Assumptions!$C$59)))*Assumptions!$C$97+(((Assumptions!$C$39*Assumptions!$C$43*((Assumptions!$C$64*Assumptions!$C$65*Assumptions!$C$63)*((Assumptions!$C$56*D$6+Assumptions!$C$57*D$6*(1-Assumptions!$C$48)+Assumptions!$C$58*D$6*(1-Assumptions!$C$49)+Assumptions!$C$59*D$6*(1-Assumptions!$C$50))/(Assumptions!$C$56+Assumptions!$C$57+Assumptions!$C$58+Assumptions!$C$59))))+(Assumptions!$C$40*Assumptions!$C$44*((Assumptions!$C$67*Assumptions!$C$68*Assumptions!$C$63)*((Assumptions!$C$56*D$6+Assumptions!$C$57*D$6*(1-Assumptions!$C$48)+Assumptions!$C$58*D$6*(1-Assumptions!$C$49)+Assumptions!$C$59*D$6*(1-Assumptions!$C$50))/(Assumptions!$C$56+Assumptions!$C$57+Assumptions!$C$58+Assumptions!$C$59))))+(Assumptions!$C$41*Assumptions!$C$45*((Assumptions!$C$70*Assumptions!$C$71*Assumptions!$C$63)*((Assumptions!$C$56*D$6+Assumptions!$C$57*D$6*(1-Assumptions!$C$48)+Assumptions!$C$58*D$6*(1-Assumptions!$C$49)+Assumptions!$C$59*D$6*(1-Assumptions!$C$50))/(Assumptions!$C$56+Assumptions!$C$57+Assumptions!$C$58+Assumptions!$C$59)))))*Assumptions!$C$92*Assumptions!$C$97) | E11: =Assumptions!$G$89*Assumptions!$C$90*($B11*((Assumptions!$C$56*E$6+Assumptions!$C$57*E$6*(1-Assumptions!$C$48)+Assumptions!$C$58*E$6*(1-Assumptions!$C$49)+Assumptions!$C$59*E$6*(1-Assumptions!$C$50))/(Assumptions!$C$56+Assumptions!$C$57+Assumptions!$C$58+Assumptions!$C$59)))*Assumptions!$C$97+(((Assumptions!$C$39*Assumptions!$C$43*((Assumptions!$C$64*Assumptions!$C$65*Assumptions!$C$63)*((Assumptions!$C$56*E$6+Assumptions!$C$57*E$6*(1-Assumptions!$C$48)+Assumptions!$C$58*E$6*(1-Assumptions!$C$49)+Assumptions!$C$59*E$6*(1-Assumptions!$C$50))/(Assumptions!$C$56+Assumptions!$C$57+Assumptions!$C$58+Assumptions!$C$59))))+(Assumptions!$C$40*Assumptions!$C$44*((Assumptions!$C$67*Assumptions!$C$68*Assumptions!$C$63)*((Assumptions!$C$56*E$6+Assumptions!$C$57*E$6*(1-Assumptions!$C$48)+Assumptions!$C$58*E$6*(1-Assumptions!$C$49)+Assumptions!$C$59*E$6*(1-Assumptions!$C$50))/(Assumptions!$C$56+Assumptions!$C$57+Assumptions!$C$58+Assumptions!$C$59))))+(Assumptions!$C$41*Assumptions!$C$45*((Assumptions!$C$70*Assumptions!$C$71*Assumptions!$C$63)*((Assumptions!$C$56*E$6+Assumptions!$C$57*E$6*(1-Assumptions!$C$48)+Assumptions!$C$58*E$6*(1-Assumptions!$C$49)+Assumptions!$C$59*E$6*(1-Assumptions!$C$50))/(Assumptions!$C$56+Assumptions!$C$57+Assumptions!$C$58+Assumptions!$C$59)))))*Assumptions!$C$92*Assumptions!$C$97) | F11: =Assumptions!$G$89*Assumptions!$C$90*($B11*((Assumptions!$C$56*F$6+Assumptions!$C$57*F$6*(1-Assumptions!$C$48)+Assumptions!$C$58*F$6*(1-Assumptions!$C$49)+Assumptions!$C$59*F$6*(1-Assumptions!$C$50))/(Assumptions!$C$56+Assumptions!$C$57+Assumptions!$C$58+Assumptions!$C$59)))*Assumptions!$C$97+(((Assumptions!$C$39*Assumptions!$C$43*((Assumptions!$C$64*Assumptions!$C$65*Assumptions!$C$63)*((Assumptions!$C$56*F$6+Assumptions!$C$57*F$6*(1-Assumptions!$C$48)+Assumptions!$C$58*F$6*(1-Assumptions!$C$49)+Assumptions!$C$59*F$6*(1-Assumptions!$C$50))/(Assumptions!$C$56+Assumptions!$C$57+Assumptions!$C$58+Assumptions!$C$59))))+(Assumptions!$C$40*Assumptions!$C$44*((Assumptions!$C$67*Assumptions!$C$68*Assumptions!$C$63)*((Assumptions!$C$56*F$6+Assumptions!$C$57*F$6*(1-Assumptions!$C$48)+Assumptions!$C$58*F$6*(1-Assumptions!$C$49)+Assumptions!$C$59*F$6*(1-Assumptions!$C$50))/(Assumptions!$C$56+Assumptions!$C$57+Assumptions!$C$58+Assumptions!$C$59))))+(Assumptions!$C$41*Assumptions!$C$45*((Assumptions!$C$70*Assumptions!$C$71*Assumptions!$C$63)*((Assumptions!$C$56*F$6+Assumptions!$C$57*F$6*(1-Assumptions!$C$48)+Assumptions!$C$58*F$6*(1-Assumptions!$C$49)+Assumptions!$C$59*F$6*(1-Assumptions!$C$50))/(Assumptions!$C$56+Assumptions!$C$57+Assumptions!$C$58+Assumptions!$C$59)))))*Assumptions!$C$92*Assumptions!$C$97) | G11: =Assumptions!$G$89*Assumptions!$C$90*($B11*((Assumptions!$C$56*G$6+Assumptions!$C$57*G$6*(1-Assumptions!$C$48)+Assumptions!$C$58*G$6*(1-Assumptions!$C$49)+Assumptions!$C$59*G$6*(1-Assumptions!$C$50))/(Assumptions!$C$56+Assumptions!$C$57+Assumptions!$C$58+Assumptions!$C$59)))*Assumptions!$C$97+(((Assumptions!$C$39*Assumptions!$C$43*((Assumptions!$C$64*Assumptions!$C$65*Assumptions!$C$63)*((Assumptions!$C$56*G$6+Assumptions!$C$57*G$6*(1-Assumptions!$C$48)+Assumptions!$C$58*G$6*(1-Assumptions!$C$49)+Assumptions!$C$59*G$6*(1-Assumptions!$C$50))/(Assumptions!$C$56+Assumptions!$C$57+Assumptions!$C$58+Assumptions!$C$59))))+(Assumptions!$C$40*Assumptions!$C$44*((Assumptions!$C$67*Assumptions!$C$68*Assumptions!$C$63)*((Assumptions!$C$56*G$6+Assumptions!$C$57*G$6*(1-Assumptions!$C$48)+Assumptions!$C$58*G$6*(1-Assumptions!$C$49)+Assumptions!$C$59*G$6*(1-Assumptions!$C$50))/(Assumptions!$C$56+Assumptions!$C$57+Assumptions!$C$58+Assumptions!$C$59))))+(Assumptions!$C$41*Assumptions!$C$45*((Assumptions!$C$70*Assumptions!$C$71*Assumptions!$C$63)*((Assumptions!$C$56*G$6+Assumptions!$C$57*G$6*(1-Assumptions!$C$48)+Assumptions!$C$58*G$6*(1-Assumptions!$C$49)+Assumptions!$C$59*G$6*(1-Assumptions!$C$50))/(Assumptions!$C$56+Assumptions!$C$57+Assumptions!$C$58+Assumptions!$C$59)))))*Assumptions!$C$92*Assumptions!$C$97)
B13: Table 2: SOM (Yr3) - Channel attach scalar vs Channel tests/account
B14: attach x \ tests/acct | C14: 100 | D14: 150 | E14: 200 | F14: 250 | G14: 300
B15: 0.5 | C15: =Assumptions!$G$89*$B15*(C$14*((Assumptions!$C$56*Assumptions!$C$47+Assumptions!$C$57*Assumptions!$C$47*(1-Assumptions!$C$48)+Assumptions!$C$58*Assumptions!$C$47*(1-Assumptions!$C$49)+Assumptions!$C$59*Assumptions!$C$47*(1-Assumptions!$C$50))/(Assumptions!$C$56+Assumptions!$C$57+Assumptions!$C$58+Assumptions!$C$59)))*Assumptions!$C$97+(((Assumptions!$C$39*Assumptions!$C$43*((Assumptions!$C$64*Assumptions!$C$65*Assumptions!$C$63)*((Assumptions!$C$56*Assumptions!$C$47+Assumptions!$C$57*Assumptions!$C$47*(1-Assumptions!$C$48)+Assumptions!$C$58*Assumptions!$C$47*(1-Assumptions!$C$49)+Assumptions!$C$59*Assumptions!$C$47*(1-Assumptions!$C$50))/(Assumptions!$C$56+Assumptions!$C$57+Assumptions!$C$58+Assumptions!$C$59))))+(Assumptions!$C$40*Assumptions!$C$44*((Assumptions!$C$67*Assumptions!$C$68*Assumptions!$C$63)*((Assumptions!$C$56*Assumptions!$C$47+Assumptions!$C$57*Assumptions!$C$47*(1-Assumptions!$C$48)+Assumptions!$C$58*Assumptions!$C$47*(1-Assumptions!$C$49)+Assumptions!$C$59*Assumptions!$C$47*(1-Assumptions!$C$50))/(Assumptions!$C$56+Assumptions!$C$57+Assumptions!$C$58+Assumptions!$C$59))))+(Assumptions!$C$41*Assumptions!$C$45*((Assumptions!$C$70*Assumptions!$C$71*Assumptions!$C$63)*((Assumptions!$C$56*Assumptions!$C$47+Assumptions!$C$57*Assumptions!$C$47*(1-Assumptions!$C$48)+Assumptions!$C$58*Assumptions!$C$47*(1-Assumptions!$C$49)+Assumptions!$C$59*Assumptions!$C$47*(1-Assumptions!$C$50))/(Assumptions!$C$56+Assumptions!$C$57+Assumptions!$C$58+Assumptions!$C$59)))))*Assumptions!$C$92*Assumptions!$C$97) | D15: =Assumptions!$G$89*$B15*(D$14*((Assumptions!$C$56*Assumptions!$C$47+Assumptions!$C$57*Assumptions!$C$47*(1-Assumptions!$C$48)+Assumptions!$C$58*Assumptions!$C$47*(1-Assumptions!$C$49)+Assumptions!$C$59*Assumptions!$C$47*(1-Assumptions!$C$50))/(Assumptions!$C$56+Assumptions!$C$57+Assumptions!$C$58+Assumptions!$C$59)))*Assumptions!$C$97+(((Assumptions!$C$39*Assumptions!$C$43*((Assumptions!$C$64*Assumptions!$C$65*Assumptions!$C$63)*((Assumptions!$C$56*Assumptions!$C$47+Assumptions!$C$57*Assumptions!$C$47*(1-Assumptions!$C$48)+Assumptions!$C$58*Assumptions!$C$47*(1-Assumptions!$C$49)+Assumptions!$C$59*Assumptions!$C$47*(1-Assumptions!$C$50))/(Assumptions!$C$56+Assumptions!$C$57+Assumptions!$C$58+Assumptions!$C$59))))+(Assumptions!$C$40*Assumptions!$C$44*((Assumptions!$C$67*Assumptions!$C$68*Assumptions!$C$63)*((Assumptions!$C$56*Assumptions!$C$47+Assumptions!$C$57*Assumptions!$C$47*(1-Assumptions!$C$48)+Assumptions!$C$58*Assumptions!$C$47*(1-Assumptions!$C$49)+Assumptions!$C$59*Assumptions!$C$47*(1-Assumptions!$C$50))/(Assumptions!$C$56+Assumptions!$C$57+Assumptions!$C$58+Assumptions!$C$59))))+(Assumptions!$C$41*Assumptions!$C$45*((Assumptions!$C$70*Assumptions!$C$71*Assumptions!$C$63)*((Assumptions!$C$56*Assumptions!$C$47+Assumptions!$C$57*Assumptions!$C$47*(1-Assumptions!$C$48)+Assumptions!$C$58*Assumptions!$C$47*(1-Assumptions!$C$49)+Assumptions!$C$59*Assumptions!$C$47*(1-Assumptions!$C$50))/(Assumptions!$C$56+Assumptions!$C$57+Assumptions!$C$58+Assumptions!$C$59)))))*Assumptions!$C$92*Assumptions!$C$97) | E15: =Assumptions!$G$89*$B15*(E$14*((Assumptions!$C$56*Assumptions!$C$47+Assumptions!$C$57*Assumptions!$C$47*(1-Assumptions!$C$48)+Assumptions!$C$58*Assumptions!$C$47*(1-Assumptions!$C$49)+Assumptions!$C$59*Assumptions!$C$47*(1-Assumptions!$C$50))/(Assumptions!$C$56+Assumptions!$C$57+Assumptions!$C$58+Assumptions!$C$59)))*Assumptions!$C$97+(((Assumptions!$C$39*Assumptions!$C$43*((Assumptions!$C$64*Assumptions!$C$65*Assumptions!$C$63)*((Assumptions!$C$56*Assumptions!$C$47+Assumptions!$C$57*Assumptions!$C$47*(1-Assumptions!$C$48)+Assumptions!$C$58*Assumptions!$C$47*(1-Assumptions!$C$49)+Assumptions!$C$59*Assumptions!$C$47*(1-Assumptions!$C$50))/(Assumptions!$C$56+Assumptions!$C$57+Assumptions!$C$58+Assumptions!$C$59))))+(Assumptions!$C$40*Assumptions!$C$44*((Assumptions!$C$67*Assumptions!$C$68*Assumptions!$C$63)*((Assumptions!$C$56*Assumptions!$C$47+Assumptions!$C$57*Assumptions!$C$47*(1-Assumptions!$C$48)+Assumptions!$C$58*Assumptions!$C$47*(1-Assumptions!$C$49)+Assumptions!$C$59*Assumptions!$C$47*(1-Assumptions!$C$50))/(Assumptions!$C$56+Assumptions!$C$57+Assumptions!$C$58+Assumptions!$C$59))))+(Assumptions!$C$41*Assumptions!$C$45*((Assumptions!$C$70*Assumptions!$C$71*Assumptions!$C$63)*((Assumptions!$C$56*Assumptions!$C$47+Assumptions!$C$57*Assumptions!$C$47*(1-Assumptions!$C$48)+Assumptions!$C$58*Assumptions!$C$47*(1-Assumptions!$C$49)+Assumptions!$C$59*Assumptions!$C$47*(1-Assumptions!$C$50))/(Assumptions!$C$56+Assumptions!$C$57+Assumptions!$C$58+Assumptions!$C$59)))))*Assumptions!$C$92*Assumptions!$C$97) | F15: =Assumptions!$G$89*$B15*(F$14*((Assumptions!$C$56*Assumptions!$C$47+Assumptions!$C$57*Assumptions!$C$47*(1-Assumptions!$C$48)+Assumptions!$C$58*Assumptions!$C$47*(1-Assumptions!$C$49)+Assumptions!$C$59*Assumptions!$C$47*(1-Assumptions!$C$50))/(Assumptions!$C$56+Assumptions!$C$57+Assumptions!$C$58+Assumptions!$C$59)))*Assumptions!$C$97+(((Assumptions!$C$39*Assumptions!$C$43*((Assumptions!$C$64*Assumptions!$C$65*Assumptions!$C$63)*((Assumptions!$C$56*Assumptions!$C$47+Assumptions!$C$57*Assumptions!$C$47*(1-Assumptions!$C$48)+Assumptions!$C$58*Assumptions!$C$47*(1-Assumptions!$C$49)+Assumptions!$C$59*Assumptions!$C$47*(1-Assumptions!$C$50))/(Assumptions!$C$56+Assumptions!$C$57+Assumptions!$C$58+Assumptions!$C$59))))+(Assumptions!$C$40*Assumptions!$C$44*((Assumptions!$C$67*Assumptions!$C$68*Assumptions!$C$63)*((Assumptions!$C$56*Assumptions!$C$47+Assumptions!$C$57*Assumptions!$C$47*(1-Assumptions!$C$48)+Assumptions!$C$58*Assumptions!$C$47*(1-Assumptions!$C$49)+Assumptions!$C$59*Assumptions!$C$47*(1-Assumptions!$C$50))/(Assumptions!$C$56+Assumptions!$C$57+Assumptions!$C$58+Assumptions!$C$59))))+(Assumptions!$C$41*Assumptions!$C$45*((Assumptions!$C$70*Assumptions!$C$71*Assumptions!$C$63)*((Assumptions!$C$56*Assumptions!$C$47+Assumptions!$C$57*Assumptions!$C$47*(1-Assumptions!$C$48)+Assumptions!$C$58*Assumptions!$C$47*(1-Assumptions!$C$49)+Assumptions!$C$59*Assumptions!$C$47*(1-Assumptions!$C$50))/(Assumptions!$C$56+Assumptions!$C$57+Assumptions!$C$58+Assumptions!$C$59)))))*Assumptions!$C$92*Assumptions!$C$97) | G15: =Assumptions!$G$89*$B15*(G$14*((Assumptions!$C$56*Assumptions!$C$47+Assumptions!$C$57*Assumptions!$C$47*(1-Assumptions!$C$48)+Assumptions!$C$58*Assumptions!$C$47*(1-Assumptions!$C$49)+Assumptions!$C$59*Assumptions!$C$47*(1-Assumptions!$C$50))/(Assumptions!$C$56+Assumptions!$C$57+Assumptions!$C$58+Assumptions!$C$59)))*Assumptions!$C$97+(((Assumptions!$C$39*Assumptions!$C$43*((Assumptions!$C$64*Assumptions!$C$65*Assumptions!$C$63)*((Assumptions!$C$56*Assumptions!$C$47+Assumptions!$C$57*Assumptions!$C$47*(1-Assumptions!$C$48)+Assumptions!$C$58*Assumptions!$C$47*(1-Assumptions!$C$49)+Assumptions!$C$59*Assumptions!$C$47*(1-Assumptions!$C$50))/(Assumptions!$C$56+Assumptions!$C$57+Assumptions!$C$58+Assumptions!$C$59))))+(Assumptions!$C$40*Assumptions!$C$44*((Assumptions!$C$67*Assumptions!$C$68*Assumptions!$C$63)*((Assumptions!$C$56*Assumptions!$C$47+Assumptions!$C$57*Assumptions!$C$47*(1-Assumptions!$C$48)+Assumptions!$C$58*Assumptions!$C$47*(1-Assumptions!$C$49)+Assumptions!$C$59*Assumptions!$C$47*(1-Assumptions!$C$50))/(Assumptions!$C$56+Assumptions!$C$57+Assumptions!$C$58+Assumptions!$C$59))))+(Assumptions!$C$41*Assumptions!$C$45*((Assumptions!$C$70*Assumptions!$C$71*Assumptions!$C$63)*((Assumptions!$C$56*Assumptions!$C$47+Assumptions!$C$57*Assumptions!$C$47*(1-Assumptions!$C$48)+Assumptions!$C$58*Assumptions!$C$47*(1-Assumptions!$C$49)+Assumptions!$C$59*Assumptions!$C$47*(1-Assumptions!$C$50))/(Assumptions!$C$56+Assumptions!$C$57+Assumptions!$C$58+Assumptions!$C$59)))))*Assumptions!$C$92*Assumptions!$C$97)
